<?xml version="1.0"?>
<robot name="one_dof">

    <link name="world" />

    <link name="base_link">
    </link>

    <link name="link_1">
        <visual>
            <origin xyz="0.0 0.0 0.0" rpy="0.0 1.57 0.0" />
            <geometry>
                <cylinder radius="0.05" length="0.1" />
            </geometry>
            <material name="green">
                <color rgba="0.0 1.0 0.0 1.0" />
            </material>
        </visual>
        <collision>
            <geometry>
                <cylinder radius="0.05" length="0.1" />
            </geometry>
        </collision>

        <visual>
            <origin xyz="0.0 0.0 0.5" rpy="0.0 0.0 0.0" />
            <geometry>
                <cylinder radius="0.05" length="0.9" />
            </geometry>
            <material name="green">
                <color rgba="0.0 1.0 0.0 1.0" />
            </material>
        </visual>
        <collision>
            <geometry>
                <cylinder radius="0.05" length="0.9" />
            </geometry>
        </collision>
        <inertial>
            <origin xyz="0 0 0" rpy="0 0 0" />
            <mass value="1" />
            <inertia ixx="0.083" ixy="0.0" ixz="0.0" iyy="0.083" iyz="0.0" izz="0.00125" />
        </inertial>
    </link>

    <link name="link_tcp">
        <visual>
            <origin xyz="0.0 0.0 0.0" rpy="0.0 0.0 0.0" />
            <geometry>
                <sphere radius="0.03"/>
            </geometry>
            <material name="yellow">
                <color rgba="1.0 1.0 0.0 1.0" />
            </material>
        </visual>
        <collision>
            <geometry>
                <sphere radius="0.05"/>
            </geometry>
        </collision>
    </link>

    <joint name="joint_fixed" type="fixed">
        <parent link="world" />
        <child link="base_link" />
        <origin xyz="0.0 0.0 0.0" rpy="0.0 1.57 0.0" />
    </joint>

    <joint name="joint_1" type="revolute">
        <origin xyz="0.0 0.0 0.0" rpy="0.0 0 0.0" />
        <parent link="base_link" />
        <child link="link_1" />
        <axis xyz="1.0 0.0 0.0" />
        <limit lower="-3.14" upper="3.14" effort="10.0" velocity="1.0" />
    </joint>

    <joint name="joint_tcp" type="revolute">
        <origin xyz="0.0 0.0 1.0" rpy="0.0 0.0 0.0" />
        <parent link="link_1" />
        <child link="link_tcp" />
        <axis xyz="0.0 0.0 1.0" />
        <limit lower="-3.14" upper="3.14" effort="10.0" velocity="1.0" />        
    </joint>


</robot>